[2022-10-28T14:30:45.106+0000] {taskinstance.py:1165} INFO - Dependencies all met for <TaskInstance: ml_pipeline.training_and_retraining_the_model.training_model manual__2022-10-28T14:26:00.172968+00:00 [queued]>
[2022-10-28T14:30:45.191+0000] {taskinstance.py:1165} INFO - Dependencies all met for <TaskInstance: ml_pipeline.training_and_retraining_the_model.training_model manual__2022-10-28T14:26:00.172968+00:00 [queued]>
[2022-10-28T14:30:45.192+0000] {taskinstance.py:1362} INFO - 
--------------------------------------------------------------------------------
[2022-10-28T14:30:45.192+0000] {taskinstance.py:1363} INFO - Starting attempt 1 of 1
[2022-10-28T14:30:45.192+0000] {taskinstance.py:1364} INFO - 
--------------------------------------------------------------------------------
[2022-10-28T14:30:45.286+0000] {taskinstance.py:1383} INFO - Executing <Task(PythonOperator): training_and_retraining_the_model.training_model> on 2022-10-28 14:26:00.172968+00:00
[2022-10-28T14:30:45.340+0000] {standard_task_runner.py:54} INFO - Started process 273 to run task
[2022-10-28T14:30:45.359+0000] {standard_task_runner.py:82} INFO - Running: ['***', 'tasks', 'run', 'ml_pipeline', 'training_and_retraining_the_model.training_model', 'manual__2022-10-28T14:26:00.172968+00:00', '--job-id', '116', '--raw', '--subdir', 'DAGS_FOLDER/ml_pipeline.py', '--cfg-path', '/tmp/tmpixuxz8ue']
[2022-10-28T14:30:45.362+0000] {standard_task_runner.py:83} INFO - Job 116: Subtask training_and_retraining_the_model.training_model
[2022-10-28T14:30:45.376+0000] {dagbag.py:525} INFO - Filling up the DagBag from /opt/***/dags/ml_pipeline.py
[2022-10-28T14:30:53.578+0000] {task_command.py:384} INFO - Running <TaskInstance: ml_pipeline.training_and_retraining_the_model.training_model manual__2022-10-28T14:26:00.172968+00:00 [running]> on host 199af5647eed
[2022-10-28T14:30:54.000+0000] {taskinstance.py:1592} INFO - Exporting the following env vars:
AIRFLOW_CTX_DAG_OWNER=Luka Perkovic
AIRFLOW_CTX_DAG_ID=ml_pipeline
AIRFLOW_CTX_TASK_ID=training_and_retraining_the_model.training_model
AIRFLOW_CTX_EXECUTION_DATE=2022-10-28T14:26:00.172968+00:00
AIRFLOW_CTX_TRY_NUMBER=1
AIRFLOW_CTX_DAG_RUN_ID=manual__2022-10-28T14:26:00.172968+00:00
[2022-10-28T14:30:54.010+0000] {taskinstance.py:1851} ERROR - Task failed with exception
Traceback (most recent call last):
  File "/home/airflow/.local/lib/python3.7/site-packages/airflow/operators/python.py", line 175, in execute
    return_value = self.execute_callable()
  File "/home/airflow/.local/lib/python3.7/site-packages/airflow/operators/python.py", line 193, in execute_callable
    return self.python_callable(*self.op_args, **self.op_kwargs)
  File "/opt/airflow/dags/scripts/train_model.py", line 17, in train_model
    df = read_file(os.path.join(DATA_DIR,'data_batch_transformed'))
  File "/opt/airflow/dags/scripts/handle_file.py", line 16, in read_file
    df = pd.read_csv(PATH)
  File "/home/airflow/.local/lib/python3.7/site-packages/pandas/util/_decorators.py", line 311, in wrapper
    return func(*args, **kwargs)
  File "/home/airflow/.local/lib/python3.7/site-packages/pandas/io/parsers/readers.py", line 586, in read_csv
    return _read(filepath_or_buffer, kwds)
  File "/home/airflow/.local/lib/python3.7/site-packages/pandas/io/parsers/readers.py", line 482, in _read
    parser = TextFileReader(filepath_or_buffer, **kwds)
  File "/home/airflow/.local/lib/python3.7/site-packages/pandas/io/parsers/readers.py", line 811, in __init__
    self._engine = self._make_engine(self.engine)
  File "/home/airflow/.local/lib/python3.7/site-packages/pandas/io/parsers/readers.py", line 1040, in _make_engine
    return mapping[engine](self.f, **self.options)  # type: ignore[call-arg]
  File "/home/airflow/.local/lib/python3.7/site-packages/pandas/io/parsers/c_parser_wrapper.py", line 51, in __init__
    self._open_handles(src, kwds)
  File "/home/airflow/.local/lib/python3.7/site-packages/pandas/io/parsers/base_parser.py", line 229, in _open_handles
    errors=kwds.get("encoding_errors", "strict"),
  File "/home/airflow/.local/lib/python3.7/site-packages/pandas/io/common.py", line 707, in get_handle
    newline="",
FileNotFoundError: [Errno 2] No such file or directory: '/opt/airflow/data/data_batch_transformed'
[2022-10-28T14:30:54.172+0000] {taskinstance.py:1406} INFO - Marking task as FAILED. dag_id=ml_pipeline, task_id=training_and_retraining_the_model.training_model, execution_date=20221028T142600, start_date=20221028T143045, end_date=20221028T143054
[2022-10-28T14:30:54.285+0000] {standard_task_runner.py:107} ERROR - Failed to execute job 116 for task training_and_retraining_the_model.training_model ([Errno 2] No such file or directory: '/opt/airflow/data/data_batch_transformed'; 273)
[2022-10-28T14:30:54.394+0000] {local_task_job.py:164} INFO - Task exited with return code 1
[2022-10-28T14:30:54.505+0000] {local_task_job.py:273} INFO - 0 downstream tasks scheduled from follow-on schedule check
