[2022-10-28T13:21:10.209+0000] {taskinstance.py:1165} INFO - Dependencies all met for <TaskInstance: ml_pipeline.processing_data manual__2022-10-28T13:20:59.795638+00:00 [queued]>
[2022-10-28T13:21:10.263+0000] {taskinstance.py:1165} INFO - Dependencies all met for <TaskInstance: ml_pipeline.processing_data manual__2022-10-28T13:20:59.795638+00:00 [queued]>
[2022-10-28T13:21:10.263+0000] {taskinstance.py:1362} INFO - 
--------------------------------------------------------------------------------
[2022-10-28T13:21:10.263+0000] {taskinstance.py:1363} INFO - Starting attempt 1 of 1
[2022-10-28T13:21:10.263+0000] {taskinstance.py:1364} INFO - 
--------------------------------------------------------------------------------
[2022-10-28T13:21:10.342+0000] {taskinstance.py:1383} INFO - Executing <Task(PythonOperator): processing_data> on 2022-10-28 13:20:59.795638+00:00
[2022-10-28T13:21:10.348+0000] {standard_task_runner.py:54} INFO - Started process 219 to run task
[2022-10-28T13:21:10.377+0000] {standard_task_runner.py:82} INFO - Running: ['***', 'tasks', 'run', 'ml_pipeline', 'processing_data', 'manual__2022-10-28T13:20:59.795638+00:00', '--job-id', '99', '--raw', '--subdir', 'DAGS_FOLDER/ml_pipeline.py', '--cfg-path', '/tmp/tmpcb75fe4f']
[2022-10-28T13:21:10.379+0000] {standard_task_runner.py:83} INFO - Job 99: Subtask processing_data
[2022-10-28T13:21:10.404+0000] {dagbag.py:525} INFO - Filling up the DagBag from /opt/***/dags/ml_pipeline.py
[2022-10-28T13:21:19.886+0000] {task_command.py:384} INFO - Running <TaskInstance: ml_pipeline.processing_data manual__2022-10-28T13:20:59.795638+00:00 [running]> on host 77e1c79bb48a
[2022-10-28T13:21:20.679+0000] {taskinstance.py:1592} INFO - Exporting the following env vars:
AIRFLOW_CTX_DAG_OWNER=Luka Perkovic
AIRFLOW_CTX_DAG_ID=ml_pipeline
AIRFLOW_CTX_TASK_ID=processing_data
AIRFLOW_CTX_EXECUTION_DATE=2022-10-28T13:20:59.795638+00:00
AIRFLOW_CTX_TRY_NUMBER=1
AIRFLOW_CTX_DAG_RUN_ID=manual__2022-10-28T13:20:59.795638+00:00
[2022-10-28T13:21:47.475+0000] {taskinstance.py:1851} ERROR - Task failed with exception
Traceback (most recent call last):
  File "/home/airflow/.local/lib/python3.7/site-packages/airflow/operators/python.py", line 175, in execute
    return_value = self.execute_callable()
  File "/home/airflow/.local/lib/python3.7/site-packages/airflow/operators/python.py", line 193, in execute_callable
    return self.python_callable(*self.op_args, **self.op_kwargs)
  File "/opt/airflow/dags/scripts/preprocess_data.py", line 41, in preprocess_data
    save_file(pd.DataFrame(data=scaler.fit_transform(df), columns=df.columns), 'data_batch_transformed.csv')
  File "/opt/airflow/dags/scripts/handle_file.py", line 22, in save_file
    delete_file(file_name)
  File "/opt/airflow/dags/scripts/handle_file.py", line 26, in delete_file
    if os.path.exists(DATA_DIR, file_name):
TypeError: exists() takes 1 positional argument but 2 were given
[2022-10-28T13:21:47.849+0000] {taskinstance.py:1406} INFO - Marking task as FAILED. dag_id=ml_pipeline, task_id=processing_data, execution_date=20221028T132059, start_date=20221028T132110, end_date=20221028T132147
[2022-10-28T13:21:48.846+0000] {standard_task_runner.py:107} ERROR - Failed to execute job 99 for task processing_data (exists() takes 1 positional argument but 2 were given; 219)
[2022-10-28T13:21:49.126+0000] {local_task_job.py:164} INFO - Task exited with return code 1
[2022-10-28T13:21:49.567+0000] {local_task_job.py:273} INFO - 0 downstream tasks scheduled from follow-on schedule check
