[2022-10-27T14:20:38.890+0000] {taskinstance.py:1165} INFO - Dependencies all met for <TaskInstance: ml_pipeline.training_and_retraining_the_model.retraining_model manual__2022-10-27T14:01:47.069341+00:00 [queued]>
[2022-10-27T14:20:38.977+0000] {taskinstance.py:1165} INFO - Dependencies all met for <TaskInstance: ml_pipeline.training_and_retraining_the_model.retraining_model manual__2022-10-27T14:01:47.069341+00:00 [queued]>
[2022-10-27T14:20:38.987+0000] {taskinstance.py:1362} INFO - 
--------------------------------------------------------------------------------
[2022-10-27T14:20:38.991+0000] {taskinstance.py:1363} INFO - Starting attempt 2 of 1
[2022-10-27T14:20:38.995+0000] {taskinstance.py:1364} INFO - 
--------------------------------------------------------------------------------
[2022-10-27T14:20:39.104+0000] {taskinstance.py:1383} INFO - Executing <Task(PythonOperator): training_and_retraining_the_model.retraining_model> on 2022-10-27 14:01:47.069341+00:00
[2022-10-27T14:20:39.150+0000] {standard_task_runner.py:82} INFO - Running: ['***', 'tasks', 'run', 'ml_pipeline', 'training_and_retraining_the_model.retraining_model', 'manual__2022-10-27T14:01:47.069341+00:00', '--job-id', '58', '--raw', '--subdir', 'DAGS_FOLDER/ml_pipeline.py', '--cfg-path', '/tmp/tmpkf5b4wkv']
[2022-10-27T14:20:39.154+0000] {standard_task_runner.py:54} INFO - Started process 170 to run task
[2022-10-27T14:20:39.183+0000] {standard_task_runner.py:83} INFO - Job 58: Subtask training_and_retraining_the_model.retraining_model
[2022-10-27T14:20:39.186+0000] {dagbag.py:525} INFO - Filling up the DagBag from /opt/***/dags/ml_pipeline.py
[2022-10-27T14:20:44.048+0000] {task_command.py:384} INFO - Running <TaskInstance: ml_pipeline.training_and_retraining_the_model.retraining_model manual__2022-10-27T14:01:47.069341+00:00 [running]> on host 89b306621d74
[2022-10-27T14:20:44.610+0000] {taskinstance.py:1592} INFO - Exporting the following env vars:
AIRFLOW_CTX_DAG_OWNER=Luka Perkovic
AIRFLOW_CTX_DAG_ID=ml_pipeline
AIRFLOW_CTX_TASK_ID=training_and_retraining_the_model.retraining_model
AIRFLOW_CTX_EXECUTION_DATE=2022-10-27T14:01:47.069341+00:00
AIRFLOW_CTX_TRY_NUMBER=2
AIRFLOW_CTX_DAG_RUN_ID=manual__2022-10-27T14:01:47.069341+00:00
[2022-10-27T14:20:44.694+0000] {taskinstance.py:1851} ERROR - Task failed with exception
Traceback (most recent call last):
  File "/home/airflow/.local/lib/python3.7/site-packages/sqlalchemy/engine/base.py", line 1803, in _execute_context
    cursor, statement, parameters, context
  File "/home/airflow/.local/lib/python3.7/site-packages/sqlalchemy/engine/default.py", line 719, in do_execute
    cursor.execute(statement, parameters)
psycopg2.errors.UndefinedTable: relation "public.batch_data" does not exist
LINE 1: SELECT * FROM public.batch_data;
                      ^


The above exception was the direct cause of the following exception:

Traceback (most recent call last):
  File "/home/airflow/.local/lib/python3.7/site-packages/airflow/operators/python.py", line 175, in execute
    return_value = self.execute_callable()
  File "/home/airflow/.local/lib/python3.7/site-packages/airflow/operators/python.py", line 193, in execute_callable
    return self.python_callable(*self.op_args, **self.op_kwargs)
  File "/opt/airflow/dags/scripts/retrain_model.py", line 17, in retrain_model
    df = load_data()
  File "/opt/airflow/dags/scripts/handle_data.py", line 34, in load_data
    df = pd.read_sql(GET_ALL_SQL, engine)
  File "/home/airflow/.local/lib/python3.7/site-packages/pandas/io/sql.py", line 634, in read_sql
    chunksize=chunksize,
  File "/home/airflow/.local/lib/python3.7/site-packages/pandas/io/sql.py", line 1579, in read_query
    result = self.execute(*args)
  File "/home/airflow/.local/lib/python3.7/site-packages/pandas/io/sql.py", line 1424, in execute
    return self.connectable.execution_options().execute(*args, **kwargs)
  File "<string>", line 2, in execute
  File "/home/airflow/.local/lib/python3.7/site-packages/sqlalchemy/util/deprecations.py", line 401, in warned
    return fn(*args, **kwargs)
  File "/home/airflow/.local/lib/python3.7/site-packages/sqlalchemy/engine/base.py", line 3139, in execute
    return connection.execute(statement, *multiparams, **params)
  File "/home/airflow/.local/lib/python3.7/site-packages/sqlalchemy/engine/base.py", line 1279, in execute
    future=False,
  File "/home/airflow/.local/lib/python3.7/site-packages/sqlalchemy/engine/base.py", line 1585, in _exec_driver_sql
    distilled_parameters,
  File "/home/airflow/.local/lib/python3.7/site-packages/sqlalchemy/engine/base.py", line 1846, in _execute_context
    e, statement, parameters, cursor, context
  File "/home/airflow/.local/lib/python3.7/site-packages/sqlalchemy/engine/base.py", line 2027, in _handle_dbapi_exception
    sqlalchemy_exception, with_traceback=exc_info[2], from_=e
  File "/home/airflow/.local/lib/python3.7/site-packages/sqlalchemy/util/compat.py", line 207, in raise_
    raise exception
  File "/home/airflow/.local/lib/python3.7/site-packages/sqlalchemy/engine/base.py", line 1803, in _execute_context
    cursor, statement, parameters, context
  File "/home/airflow/.local/lib/python3.7/site-packages/sqlalchemy/engine/default.py", line 719, in do_execute
    cursor.execute(statement, parameters)
sqlalchemy.exc.ProgrammingError: (psycopg2.errors.UndefinedTable) relation "public.batch_data" does not exist
LINE 1: SELECT * FROM public.batch_data;
                      ^

[SQL: SELECT * FROM public.batch_data;]
(Background on this error at: https://sqlalche.me/e/14/f405)
[2022-10-27T14:20:44.773+0000] {taskinstance.py:1406} INFO - Marking task as FAILED. dag_id=ml_pipeline, task_id=training_and_retraining_the_model.retraining_model, execution_date=20221027T140147, start_date=20221027T142038, end_date=20221027T142044
[2022-10-27T14:20:44.959+0000] {standard_task_runner.py:107} ERROR - Failed to execute job 58 for task training_and_retraining_the_model.retraining_model ((psycopg2.errors.UndefinedTable) relation "public.batch_data" does not exist
LINE 1: SELECT * FROM public.batch_data;
                      ^

[SQL: SELECT * FROM public.batch_data;]
(Background on this error at: https://sqlalche.me/e/14/f405); 170)
[2022-10-27T14:20:45.094+0000] {local_task_job.py:164} INFO - Task exited with return code 1
[2022-10-27T14:20:45.335+0000] {local_task_job.py:273} INFO - 0 downstream tasks scheduled from follow-on schedule check
